<mujoco model="g1_inspire">
  <compiler angle="radian" meshdir="."/>

  <option integrator="implicitfast"/>

  <default>
    <default class="g1">
      <site rgba="1 0 0 1" size="0.01" group="5"/>
      <joint armature="0.01" frictionloss="0.3"/>
      <position kp="500" dampratio="1" inheritrange="1"/>
      <default class="visual">
        <geom group="2" type="mesh" contype="0" conaffinity="0" density="0" material="metal"/>
      </default>
      <default class="collision">
        <geom group="3" type="mesh"/>
        <default class="foot">
          <geom type="sphere" size="0.005" priority="1" friction="0.6" condim="3"/>
        </default>
      </default>
    </default>
    <default class="inspire">
      <joint armature="0.005" frictionloss="0.05" damping="0.1"/>
      <position kp="2" dampratio="1"/>
    </default>
  </default>

  <asset>
    <material name="black" rgba="0.2 0.2 0.2 1"/>
    <material name="metal" rgba="0.7 0.7 0.7 1"/>

    <mesh file="g1/pelvis.STL"/>
    <mesh file="g1/pelvis_contour_link.STL"/>
    <mesh file="g1/left_hip_pitch_link.STL"/>
    <mesh file="g1/left_hip_roll_link.STL"/>
    <mesh file="g1/left_hip_yaw_link.STL"/>
    <mesh file="g1/left_knee_link.STL"/>
    <mesh file="g1/left_ankle_pitch_link.STL"/>
    <mesh file="g1/left_ankle_roll_link.STL"/>
    <mesh file="g1/right_hip_pitch_link.STL"/>
    <mesh file="g1/right_hip_roll_link.STL"/>
    <mesh file="g1/right_hip_yaw_link.STL"/>
    <mesh file="g1/right_knee_link.STL"/>
    <mesh file="g1/right_ankle_pitch_link.STL"/>
    <mesh file="g1/right_ankle_roll_link.STL"/>
    <mesh name="waist_yaw_link" file="g1/waist_yaw_link_rev_1_0.STL"/>
    <mesh name="waist_roll_link" file="g1/waist_roll_link_rev_1_0.STL"/>
    <mesh name="torso_link" file="g1/torso_link_rev_1_0.STL"/>
    <mesh file="g1/logo_link.STL"/>
    <mesh file="g1/head_link.STL"/>
    <mesh file="g1/left_shoulder_pitch_link.STL"/>
    <mesh file="g1/left_shoulder_roll_link.STL"/>
    <mesh file="g1/left_shoulder_yaw_link.STL"/>
    <mesh file="g1/left_elbow_link.STL"/>
    <mesh file="g1/left_wrist_roll_link.STL"/>
    <mesh file="g1/left_wrist_pitch_link.STL"/>
    <mesh file="g1/left_wrist_yaw_link.STL"/>
    <mesh file="g1/left_rubber_hand.STL"/>
    <mesh file="g1/right_shoulder_pitch_link.STL"/>
    <mesh file="g1/right_shoulder_roll_link.STL"/>
    <mesh file="g1/right_shoulder_yaw_link.STL"/>
    <mesh file="g1/right_elbow_link.STL"/>
    <mesh file="g1/right_wrist_roll_link.STL"/>
    <mesh file="g1/right_wrist_pitch_link.STL"/>
    <mesh file="g1/right_wrist_yaw_link.STL"/>
    <mesh file="g1/right_rubber_hand.STL"/>
    <!-- Inspire DFQ hand meshes (unitree_ros) -->
    <mesh file="inspire/L_hand_base_link.STL"/>
    <mesh file="inspire/R_hand_base_link.STL"/>
    <mesh file="inspire/Link11_L.STL"/>
    <mesh file="inspire/Link12_L.STL"/>
    <mesh file="inspire/Link13_L.STL"/>
    <mesh file="inspire/Link14_L.STL"/>
    <mesh file="inspire/Link15_L.STL"/>
    <mesh file="inspire/Link16_L.STL"/>
    <mesh file="inspire/Link17_L.STL"/>
    <mesh file="inspire/Link18_L.STL"/>
    <mesh file="inspire/Link19_L.STL"/>
    <mesh file="inspire/Link20_L.STL"/>
    <mesh file="inspire/Link21_L.STL"/>
    <mesh file="inspire/Link22_L.STL"/>
    <mesh file="inspire/Link11_R.STL"/>
    <mesh file="inspire/Link12_R.STL"/>
    <mesh file="inspire/Link13_R.STL"/>
    <mesh file="inspire/Link14_R.STL"/>
    <mesh file="inspire/Link15_R.STL"/>
    <mesh file="inspire/Link16_R.STL"/>
    <mesh file="inspire/Link17_R.STL"/>
    <mesh file="inspire/Link18_R.STL"/>
    <mesh file="inspire/Link19_R.STL"/>
    <mesh file="inspire/Link20_R.STL"/>
    <mesh file="inspire/Link21_R.STL"/>
    <mesh file="inspire/Link22_R.STL"/>
  </asset>

  <worldbody>
    <light pos="1 0 3.5" dir="0 0 -1" directional="true"/>
    <body name="pelvis" pos="0 0 0.793" childclass="g1">
      <inertial pos="0 0 -0.07605" quat="1 0 -0.000399148 0" mass="3.813" diaginertia="0.010549 0.0093089 0.0079184"/>
      <freejoint name="floating_base_joint"/>
      <geom class="visual" material="black" mesh="pelvis"/>
      <geom class="visual" mesh="pelvis_contour_link"/>
      <geom class="collision" mesh="pelvis_contour_link"/>
      <site name="imu_in_pelvis" pos="0.04525 0 -0.08339" size="0.01"/>
      <body name="left_hip_pitch_link" pos="0 0.064452 -0.1027">
        <inertial pos="0.002741 0.047791 -0.02606" quat="0.954862 0.293964 0.0302556 0.030122" mass="1.35"
          diaginertia="0.00181517 0.00153422 0.00116212"/>
        <joint name="left_hip_pitch_joint" axis="0 1 0" range="-2.5307 2.8798" actuatorfrcrange="-88 88"/>
        <geom class="visual" material="black" mesh="left_hip_pitch_link"/>
        <geom class="collision" material="black" mesh="left_hip_pitch_link"/>
        <body name="left_hip_roll_link" pos="0 0.052 -0.030465" quat="0.996179 0 -0.0873386 0">
          <inertial pos="0.029812 -0.001045 -0.087934" quat="0.977808 -1.97119e-05 0.205576 -0.0403793" mass="1.52"
            diaginertia="0.00254986 0.00241169 0.00148755"/>
          <joint name="left_hip_roll_joint" axis="1 0 0" range="-0.5236 2.9671" actuatorfrcrange="-139 139"/>
          <geom class="visual" mesh="left_hip_roll_link"/>
          <geom class="collision" mesh="left_hip_roll_link"/>
          <body name="left_hip_yaw_link" pos="0.025001 0 -0.12412">
            <inertial pos="-0.057709 -0.010981 -0.15078" quat="0.600598 0.15832 0.223482 0.751181" mass="1.702"
              diaginertia="0.00776166 0.00717575 0.00160139"/>
            <joint name="left_hip_yaw_joint" axis="0 0 1" range="-2.7576 2.7576" actuatorfrcrange="-88 88"/>
            <geom class="visual" mesh="left_hip_yaw_link"/>
            <geom class="collision" mesh="left_hip_yaw_link"/>
            <body name="left_knee_link" pos="-0.078273 0.0021489 -0.17734" quat="0.996179 0 0.0873386 0">
              <inertial pos="0.005457 0.003964 -0.12074" quat="0.923418 -0.0327699 0.0158246 0.382067" mass="1.932"
                diaginertia="0.0113804 0.0112778 0.00146458"/>
              <joint name="left_knee_joint" axis="0 1 0" range="-0.087267 2.8798" actuatorfrcrange="-139 139"/>
              <geom class="visual" mesh="left_knee_link"/>
              <geom class="collision" mesh="left_knee_link"/>
              <body name="left_ankle_pitch_link" pos="0 -9.4445e-05 -0.30001">
                <inertial pos="-0.007269 0 0.011137" quat="0.603053 0.369225 0.369225 0.603053" mass="0.074"
                  diaginertia="1.89e-05 1.40805e-05 6.9195e-06"/>
                <joint name="left_ankle_pitch_joint" axis="0 1 0" range="-0.87267 0.5236" actuatorfrcrange="-50 50"/>
                <geom class="visual" mesh="left_ankle_pitch_link"/>
                <geom class="collision" mesh="left_ankle_pitch_link"/>
                <body name="left_ankle_roll_link" pos="0 0 -0.017558">
                  <inertial pos="0.026505 0 -0.016425" quat="-0.000481092 0.728482 -0.000618967 0.685065" mass="0.608"
                    diaginertia="0.00167218 0.0016161 0.000217621"/>
                  <joint name="left_ankle_roll_joint" axis="1 0 0" range="-0.2618 0.2618" actuatorfrcrange="-50 50"/>
                  <geom class="visual" material="black" mesh="left_ankle_roll_link"/>
                  <geom class="foot" pos="-0.05 0.025 -0.03"/>
                  <geom class="foot" pos="-0.05 -0.025 -0.03"/>
                  <geom class="foot" pos="0.12 0.03 -0.03"/>
                  <geom class="foot" pos="0.12 -0.03 -0.03"/>
                  <site name="left_foot"/>
                </body>
              </body>
            </body>
          </body>
        </body>
      </body>
      <body name="right_hip_pitch_link" pos="0 -0.064452 -0.1027">
        <inertial pos="0.002741 -0.047791 -0.02606" quat="0.954862 -0.293964 0.0302556 -0.030122" mass="1.35"
          diaginertia="0.00181517 0.00153422 0.00116212"/>
        <joint name="right_hip_pitch_joint" axis="0 1 0" range="-2.5307 2.8798" actuatorfrcrange="-88 88"/>
        <geom class="visual" material="black" mesh="right_hip_pitch_link"/>
        <geom class="collision" material="black" mesh="right_hip_pitch_link"/>
        <body name="right_hip_roll_link" pos="0 -0.052 -0.030465" quat="0.996179 0 -0.0873386 0">
          <inertial pos="0.029812 0.001045 -0.087934" quat="0.977808 1.97119e-05 0.205576 0.0403793" mass="1.52"
            diaginertia="0.00254986 0.00241169 0.00148755"/>
          <joint name="right_hip_roll_joint" axis="1 0 0" range="-2.9671 0.5236" actuatorfrcrange="-139 139"/>
          <geom class="visual" mesh="right_hip_roll_link"/>
          <geom class="collision" mesh="right_hip_roll_link"/>
          <body name="right_hip_yaw_link" pos="0.025001 0 -0.12412">
            <inertial pos="-0.057709 0.010981 -0.15078" quat="0.751181 0.223482 0.15832 0.600598" mass="1.702"
              diaginertia="0.00776166 0.00717575 0.00160139"/>
            <joint name="right_hip_yaw_joint" axis="0 0 1" range="-2.7576 2.7576" actuatorfrcrange="-88 88"/>
            <geom class="visual" mesh="right_hip_yaw_link"/>
            <geom class="collision" mesh="right_hip_yaw_link"/>
            <body name="right_knee_link" pos="-0.078273 -0.0021489 -0.17734" quat="0.996179 0 0.0873386 0">
              <inertial pos="0.005457 -0.003964 -0.12074" quat="0.923439 0.0345276 0.0116333 -0.382012" mass="1.932"
                diaginertia="0.011374 0.0112843 0.00146452"/>
              <joint name="right_knee_joint" axis="0 1 0" range="-0.087267 2.8798" actuatorfrcrange="-139 139"/>
              <geom class="visual" mesh="right_knee_link"/>
              <geom class="collision" mesh="right_knee_link"/>
              <body name="right_ankle_pitch_link" pos="0 9.4445e-05 -0.30001">
                <inertial pos="-0.007269 0 0.011137" quat="0.603053 0.369225 0.369225 0.603053" mass="0.074"
                  diaginertia="1.89e-05 1.40805e-05 6.9195e-06"/>
                <joint name="right_ankle_pitch_joint" axis="0 1 0" range="-0.87267 0.5236" actuatorfrcrange="-50 50"/>
                <geom class="visual" mesh="right_ankle_pitch_link"/>
                <geom class="collision" mesh="right_ankle_pitch_link"/>
                <body name="right_ankle_roll_link" pos="0 0 -0.017558">
                  <inertial pos="0.026505 0 -0.016425" quat="0.000481092 0.728482 0.000618967 0.685065" mass="0.608"
                    diaginertia="0.00167218 0.0016161 0.000217621"/>
                  <joint name="right_ankle_roll_joint" axis="1 0 0" range="-0.2618 0.2618" actuatorfrcrange="-50 50"/>
                  <geom class="visual" material="black" mesh="right_ankle_roll_link"/>
                  <geom class="foot" pos="-0.05 0.025 -0.03"/>
                  <geom class="foot" pos="-0.05 -0.025 -0.03"/>
                  <geom class="foot" pos="0.12 0.03 -0.03"/>
                  <geom class="foot" pos="0.12 -0.03 -0.03"/>
                  <site name="right_foot"/>
                </body>
              </body>
            </body>
          </body>
        </body>
      </body>
      <body name="waist_yaw_link">
        <inertial pos="0.003494 0.000233 0.018034" quat="0.289697 0.591001 -0.337795 0.672821" mass="0.214"
          diaginertia="0.000163531 0.000107714 0.000102205"/>
        <joint name="waist_yaw_joint" axis="0 0 1" range="-2.618 2.618" actuatorfrcrange="-88 88"/>
        <geom class="visual" mesh="waist_yaw_link"/>
        <body name="waist_roll_link" pos="-0.0039635 0 0.044">
          <inertial pos="0 2.3e-05 0" quat="0.5 0.5 -0.5 0.5" mass="0.086" diaginertia="8.245e-06 7.079e-06 6.339e-06"/>
          <joint name="waist_roll_joint" axis="1 0 0" range="-0.52 0.52" actuatorfrcrange="-50 50"/>
          <geom class="visual" mesh="waist_roll_link"/>
          <body name="torso_link">
            <inertial pos="0.00203158 0.000339683 0.184568" quat="0.999803 -6.03319e-05 0.0198256 0.00131986"
              mass="7.818" diaginertia="0.121847 0.109825 0.0273735"/>
            <joint name="waist_pitch_joint" axis="0 1 0" range="-0.52 0.52" actuatorfrcrange="-50 50"/>
            <geom class="visual" mesh="torso_link"/>
            <geom class="collision" mesh="torso_link"/>
            <geom pos="0.0039635 0 -0.044" quat="1 0 0 0" class="visual" material="black" mesh="logo_link"/>
            <geom pos="0.0039635 0 -0.044" quat="1 0 0 0" class="collision" material="black" mesh="logo_link"/>
            <geom pos="0.0039635 0 -0.044" quat="1 0 0 0" class="visual" material="black" mesh="head_link"/>
            <geom pos="0.0039635 0 -0.044" quat="1 0 0 0" class="collision" material="black" mesh="head_link"/>
            <site name="imu_in_torso" pos="-0.03959 -0.00224 0.14792" size="0.01"/>
            <!-- ── POV head camera (egocentric "smart-glasses" viewpoint) ──────────────
                 Rigidly mounted on torso_link, so it moves WITH the waist lean.
                 TUNABLES (adjust to match the source-video framing):
                   POS    "x y z" = mount offset from torso origin: x forward, z up
                           (≈ eye height/forward). Current ≈ head/forehead height.
                   XYAXES "rightx righty rightz  upx upy upz" encodes the down-tilt:
                           right = (0,-1,0) (robot's right);  up = (sinθ,0,cosθ).
                           Here θ≈45° down → up = (0.707,0,0.707). Increase the first
                           component / decrease the third to look further DOWN.
                   FOVY   vertical field of view (deg); larger → more table in frame.
                 -->
            <camera name="pov_head" mode="fixed" pos="0.10 0 0.32"
                    xyaxes="0 -1 0 0.899 0 0.438" fovy="80"/>
            <body name="left_shoulder_pitch_link" pos="0.0039563 0.10022 0.24778"
              quat="0.990264 0.139201 1.38722e-05 -9.86868e-05">
              <inertial pos="0 0.035892 -0.011628" quat="0.654152 0.0130458 -0.326267 0.68225" mass="0.718"
                diaginertia="0.000465864 0.000432842 0.000406394"/>
              <joint name="left_shoulder_pitch_joint" axis="0 1 0" range="-3.0892 2.6704" actuatorfrcrange="-25 25"/>
              <geom class="visual" mesh="left_shoulder_pitch_link"/>
              <geom size="0.03 0.025" pos="0 0.04 -0.01" quat="0.707107 0 0.707107 0" type="cylinder"
                rgba="0.7 0.7 0.7 1" class="collision"/>
              <body name="left_shoulder_roll_link" pos="0 0.038 -0.013831" quat="0.990268 -0.139172 0 0">
                <inertial pos="-0.000227 0.00727 -0.063243" quat="0.701256 -0.0196223 -0.00710317 0.712604" mass="0.643"
                  diaginertia="0.000691311 0.000618011 0.000388977"/>
                <joint name="left_shoulder_roll_joint" axis="1 0 0" range="-1.5882 2.2515" actuatorfrcrange="-25 25"/>
                <geom class="visual" mesh="left_shoulder_roll_link"/>
                <geom size="0.03 0.015" pos="-0.004 0.006 -0.053" type="cylinder" rgba="0.7 0.7 0.7 1"
                  class="collision"/>
                <body name="left_shoulder_yaw_link" pos="0 0.00624 -0.1032">
                  <inertial pos="0.010773 -0.002949 -0.072009" quat="0.716879 -0.0964829 -0.0679942 0.687134"
                    mass="0.734" diaginertia="0.00106187 0.00103217 0.000400661"/>
                  <joint name="left_shoulder_yaw_joint" axis="0 0 1" range="-2.618 2.618" actuatorfrcrange="-25 25"/>
                  <geom class="visual" mesh="left_shoulder_yaw_link"/>
                  <geom class="collision" mesh="left_shoulder_yaw_link"/>
                  <body name="left_elbow_link" pos="0.015783 0 -0.080518">
                    <inertial pos="0.064956 0.004454 -0.010062" quat="0.541765 0.636132 0.388821 0.388129" mass="0.6"
                      diaginertia="0.000443035 0.000421612 0.000259353"/>
                    <joint name="left_elbow_joint" axis="0 1 0" range="-1.0472 2.0944" actuatorfrcrange="-25 25"/>
                    <geom class="visual" mesh="left_elbow_link"/>
                    <geom class="collision" mesh="left_elbow_link"/>
                    <body name="left_wrist_roll_link" pos="0.1 0.00188791 -0.01">
                      <inertial pos="0.0171394 0.000537591 4.8864e-07" quat="0.575338 0.411667 -0.574906 0.411094"
                        mass="0.085445" diaginertia="5.48211e-05 4.96646e-05 3.57798e-05"/>
                      <joint name="left_wrist_roll_joint" axis="1 0 0" range="-1.97222 1.97222"
                        actuatorfrcrange="-25 25"/>
                      <geom class="visual" mesh="left_wrist_roll_link"/>
                      <geom class="collision" mesh="left_wrist_roll_link"/>
                      <body name="left_wrist_pitch_link" pos="0.038 0 0">
                        <inertial pos="0.0229999 -0.00111685 -0.00111658" quat="0.249998 0.661363 0.293036 0.643608"
                          mass="0.48405" diaginertia="0.000430353 0.000429873 0.000164648"/>
                        <joint name="left_wrist_pitch_joint" axis="0 1 0" range="-1.61443 1.61443"
                          actuatorfrcrange="-5 5"/>
                        <geom class="visual" mesh="left_wrist_pitch_link"/>
                        <geom class="collision" mesh="left_wrist_pitch_link"/>
                        <body name="left_wrist_yaw_link" pos="0.046 0 0">
                          <inertial pos="0.0708244 0.000191745 0.00161742" quat="0.510571 0.526295 0.468078 0.493188"
                            mass="0.254576" diaginertia="0.000646113 0.000559993 0.000147566"/>
                          <joint name="left_wrist_yaw_joint" axis="0 0 1" range="-1.61443 1.61443"
                            actuatorfrcrange="-5 5"/>
                          <geom class="visual" mesh="left_wrist_yaw_link"/>
                          <geom class="collision" mesh="left_wrist_yaw_link"/>
                                                  <!-- ===== Inspire DFQ left hand (grafted; mount from unitree_ros URDF) ===== -->
                          <body name="L_hand_base_link" pos="0.0415 0 0" quat="0.70710678 0 0 0.70710678">
                              <inertial pos="-0.002551 -0.066047 -0.0019357" mass="0.14143" fullinertia="0.0001234 8.3835E-05 7.7231E-05 2.1995E-06 -1.7694E-06 1.5968E-06"/>
                              <geom class="visual" mesh="L_hand_base_link"/>
                              <geom class="collision" mesh="L_hand_base_link"/>
                            <body name="L_thumb_proximal_base" pos="-0.01696 -0.0691 0.02045" quat="0.49999816 0.5 -0.5 0.50000184">
                              <joint class="inspire" name="L_thumb_proximal_yaw_joint" axis="0 0 1" range="-0.1 1.3"/>
                                <inertial pos="0.0048817 0.00038782 -0.00722" mass="0.0018869" fullinertia="5.5158E-08 8.2164E-08 6.7434E-08 -1.1803E-08 -4.6743E-09 -1.3521E-09"/>
                                <geom class="visual" mesh="Link11_L"/>
                                <geom class="collision" mesh="Link11_L"/>
                              <body name="L_thumb_proximal" pos="0.0099867 0.0098242 -0.0089" quat="0.70457088 -0.70457347 -0.059816945 0.059816726">
                                <joint class="inspire" name="L_thumb_proximal_pitch_joint" axis="0 0 -1" range="-0.1 0.6"/>
                                  <inertial pos="0.021936 -0.01279 -0.0080386" mass="0.0066101" fullinertia="1.5693E-06 1.7356E-06 2.787E-06 7.8339E-07 8.5959E-10 1.0378E-09"/>
                                  <geom class="visual" mesh="Link12_L"/>
                                  <geom class="collision" mesh="Link12_L"/>
                                <body name="L_thumb_intermediate" pos="0.04407 -0.034553 -0.0008" quat="1 0 0 0">
                                  <joint class="inspire" name="L_thumb_intermediate_joint" axis="0 0 -1" range="0 0.8"/>
                                    <inertial pos="0.0095531 0.0016282 -0.0072002" mass="0.0037844" fullinertia="3.6981E-07 3.2395E-07 4.6532E-07 9.8603E-08 -2.8173E-12 -2.8028E-12"/>
                                    <geom class="visual" mesh="Link13_L"/>
                                    <geom class="collision" mesh="Link13_L"/>
                                  <body name="L_thumb_distal" pos="0.020248 -0.010156 -0.0012" quat="1 0 0 0">
                                    <joint class="inspire" name="L_thumb_distal_joint" axis="0 0 -1" range="0 1.2"/>
                                      <inertial pos="0.0092888 -0.004953 -0.0060033" mass="0.003344" fullinertia="1.3632E-07 1.4052E-07 2.0026E-07 5.6787E-08 -9.1939E-11 1.2145E-10"/>
                                      <geom class="visual" mesh="Link14_L"/>
                                      <geom class="collision" mesh="Link14_L"/>
                                  </body>
                                </body>
                              </body>
                            </body>
                            <body name="L_index_proximal" pos="0.00028533 -0.13653 0.032268" quat="0.99984769 -0.017452614 0 0">
                              <joint class="inspire" name="L_index_proximal_joint" axis="0 0 -1" range="0 1.7"/>
                                <inertial pos="0.0012971 -0.011934 -0.0059998" mass="0.0042405" fullinertia="6.6215E-07 2.1167E-07 6.9402E-07 1.8442E-08 1.3746E-12 -1.4773E-11"/>
                                <geom class="visual" mesh="Link15_L"/>
                                <geom class="collision" mesh="Link15_L"/>
                              <body name="L_index_intermediate" pos="-0.0024229 -0.032041 -0.001" quat="1 0 0 0">
                                <joint class="inspire" name="L_index_intermediate_joint" axis="0 0 -1" range="0 1.7"/>
                                  <inertial pos="0.0021753 -0.019567 -0.005" mass="0.0045682" fullinertia="7.6284E-07 9.4308E-08 7.8176E-07 -8.063E-08 3.6797E-13 1.5743E-13"/>
                                  <geom class="visual" mesh="Link16_L"/>
                                  <geom class="collision" mesh="Link16_L"/>
                              </body>
                            </body>
                            <body name="L_middle_proximal" pos="0.00028533 -0.1371 0.01295" quat="1 0 0 0">
                              <joint class="inspire" name="L_middle_proximal_joint" axis="0 0 -1" range="0 1.7"/>
                                <inertial pos="0.0012971 -0.011934 -0.0059999" mass="0.0042405" fullinertia="6.6215E-07 2.1167E-07 6.9402E-07 1.8442E-08 1.2299E-12 -1.4484E-11"/>
                                <geom class="visual" mesh="Link17_L"/>
                                <geom class="collision" mesh="Link17_L"/>
                              <body name="L_middle_intermediate" pos="-0.0024229 -0.032041 -0.001" quat="1 0 0 0">
                                <joint class="inspire" name="L_middle_intermediate_joint" axis="0 0 -1" range="0 1.7"/>
                                  <inertial pos="0.001921 -0.020796 -0.0049999" mass="0.0050397" fullinertia="9.5823E-07 1.0646E-07 9.8385E-07 -1.1425E-07 -2.4186E-12 3.6974E-12"/>
                                  <geom class="visual" mesh="Link18_L"/>
                                  <geom class="collision" mesh="Link18_L"/>
                              </body>
                            </body>
                            <body name="L_ring_proximal" pos="0.00028533 -0.13691 -0.0062872" quat="0.99965732 0.02617701 0 0">
                              <joint class="inspire" name="L_ring_proximal_joint" axis="0 0 -1" range="0 1.7"/>
                                <inertial pos="0.0012971 -0.011934 -0.0059999" mass="0.0042405" fullinertia="6.6215E-07 2.1167E-07 6.9402E-07 1.8442E-08 9.6052E-13 -1.4124E-11"/>
                                <geom class="visual" mesh="Link19_L"/>
                                <geom class="collision" mesh="Link19_L"/>
                              <body name="L_ring_intermediate" pos="-0.0024229 -0.032041 -0.001" quat="1 0 0 0">
                                <joint class="inspire" name="L_ring_intermediate_joint" axis="0 0 -1" range="0 1.7"/>
                                  <inertial pos="0.0021753 -0.019567 -0.005" mass="0.0045682" fullinertia="7.6285E-07 9.4308E-08 7.8176E-07 -8.0631E-08 3.3472E-14 -4.4773E-13"/>
                                  <geom class="visual" mesh="Link20_L"/>
                                  <geom class="collision" mesh="Link20_L"/>
                              </body>
                            </body>
                            <body name="L_pinky_proximal" pos="0.00028533 -0.13571 -0.025488" quat="0.99862953 0.052336079 0 0">
                              <joint class="inspire" name="L_pinky_proximal_joint" axis="0 0 -1" range="0 1.7"/>
                                <inertial pos="0.0012971 -0.011934 -0.0059999" mass="0.0042405" fullinertia="6.6215E-07 2.1167E-07 6.9402E-07 1.8442E-08 1.0279E-12 -1.4277E-11"/>
                                <geom class="visual" mesh="Link21_L"/>
                                <geom class="collision" mesh="Link21_L"/>
                              <body name="L_pinky_intermediate" pos="-0.0024229 -0.032041 -0.001" quat="1 0 0 0">
                                <joint class="inspire" name="L_pinky_intermediate_joint" axis="0 0 -1" range="0 1.7"/>
                                  <inertial pos="0.0024788 -0.016208 -0.0050001" mass="0.0036036" fullinertia="4.3923E-07 7.0315E-08 4.4881E-07 -4.1355E-08 1.2263E-12 3.1311E-12"/>
                                  <geom class="visual" mesh="Link22_L"/>
                                  <geom class="collision" mesh="Link22_L"/>
                              </body>
                            </body>
                          </body>
                        </body>
                      </body>
                    </body>
                  </body>
                </body>
              </body>
            </body>
            <body name="right_shoulder_pitch_link" pos="0.0039563 -0.10021 0.24778"
              quat="0.990264 -0.139201 1.38722e-05 9.86868e-05">
              <inertial pos="0 -0.035892 -0.011628" quat="0.68225 -0.326267 0.0130458 0.654152" mass="0.718"
                diaginertia="0.000465864 0.000432842 0.000406394"/>
              <joint name="right_shoulder_pitch_joint" axis="0 1 0" range="-3.0892 2.6704" actuatorfrcrange="-25 25"/>
              <geom class="visual" mesh="right_shoulder_pitch_link"/>
              <geom size="0.03 0.025" pos="0 -0.04 -0.01" quat="0.707107 0 0.707107 0" type="cylinder"
                rgba="0.7 0.7 0.7 1" class="collision"/>
              <body name="right_shoulder_roll_link" pos="0 -0.038 -0.013831" quat="0.990268 0.139172 0 0">
                <inertial pos="-0.000227 -0.00727 -0.063243" quat="0.712604 -0.00710317 -0.0196223 0.701256"
                  mass="0.643" diaginertia="0.000691311 0.000618011 0.000388977"/>
                <joint name="right_shoulder_roll_joint" axis="1 0 0" range="-2.2515 1.5882" actuatorfrcrange="-25 25"/>
                <geom class="visual" mesh="right_shoulder_roll_link"/>
                <geom size="0.03 0.015" pos="-0.004 -0.006 -0.053" type="cylinder" rgba="0.7 0.7 0.7 1"
                  class="collision"/>
                <body name="right_shoulder_yaw_link" pos="0 -0.00624 -0.1032">
                  <inertial pos="0.010773 0.002949 -0.072009" quat="0.687134 -0.0679942 -0.0964829 0.716879"
                    mass="0.734" diaginertia="0.00106187 0.00103217 0.000400661"/>
                  <joint name="right_shoulder_yaw_joint" axis="0 0 1" range="-2.618 2.618" actuatorfrcrange="-25 25"/>
                  <geom class="visual" mesh="right_shoulder_yaw_link"/>
                  <geom class="collision" mesh="right_shoulder_yaw_link"/>
                  <body name="right_elbow_link" pos="0.015783 0 -0.080518">
                    <inertial pos="0.064956 -0.004454 -0.010062" quat="0.388129 0.388821 0.636132 0.541765" mass="0.6"
                      diaginertia="0.000443035 0.000421612 0.000259353"/>
                    <joint name="right_elbow_joint" axis="0 1 0" range="-1.0472 2.0944" actuatorfrcrange="-25 25"/>
                    <geom class="visual" mesh="right_elbow_link"/>
                    <geom class="collision" mesh="right_elbow_link"/>
                    <body name="right_wrist_roll_link" pos="0.1 -0.00188791 -0.01">
                      <inertial pos="0.0171394 -0.000537591 4.8864e-07" quat="0.411667 0.575338 -0.411094 0.574906"
                        mass="0.085445" diaginertia="5.48211e-05 4.96646e-05 3.57798e-05"/>
                      <joint name="right_wrist_roll_joint" axis="1 0 0" range="-1.97222 1.97222"
                        actuatorfrcrange="-25 25"/>
                      <geom class="visual" mesh="right_wrist_roll_link"/>
                      <geom class="collision" mesh="right_wrist_roll_link"/>
                      <body name="right_wrist_pitch_link" pos="0.038 0 0">
                        <inertial pos="0.0229999 0.00111685 -0.00111658" quat="0.643608 0.293036 0.661363 0.249998"
                          mass="0.48405" diaginertia="0.000430353 0.000429873 0.000164648"/>
                        <joint name="right_wrist_pitch_joint" axis="0 1 0" range="-1.61443 1.61443"
                          actuatorfrcrange="-5 5"/>
                        <geom class="visual" mesh="right_wrist_pitch_link"/>
                        <geom class="collision" mesh="right_wrist_pitch_link"/>
                        <body name="right_wrist_yaw_link" pos="0.046 0 0">
                          <inertial pos="0.0708244 -0.000191745 0.00161742" quat="0.493188 0.468078 0.526295 0.510571"
                            mass="0.254576" diaginertia="0.000646113 0.000559993 0.000147566"/>
                          <joint name="right_wrist_yaw_joint" axis="0 0 1" range="-1.61443 1.61443"
                            actuatorfrcrange="-5 5"/>
                          <geom class="visual" mesh="right_wrist_yaw_link"/>
                          <geom class="collision" mesh="right_wrist_yaw_link"/>
                                                  <!-- ===== Inspire DFQ right hand (grafted; mount from unitree_ros URDF) ===== -->
                          <body name="R_hand_base_link" pos="0.0415 0 0" quat="4.3297803e-17 0.70710678 -0.70710678 -4.3297803e-17">
                              <inertial pos="-0.0025264 -0.066047 0.0019598" mass="0.14143" fullinertia="0.00012281 8.3832E-05 7.6663E-05 2.1711E-06 1.7709E-06 -1.6551E-06"/>
                              <geom class="visual" mesh="R_hand_base_link"/>
                              <geom class="collision" mesh="R_hand_base_link"/>
                            <body name="R_thumb_proximal_base" pos="-0.01696 -0.0691 -0.02045" quat="0.49999816 0.5 -0.5 0.50000184">
                              <joint class="inspire" name="R_thumb_proximal_yaw_joint" axis="0 0 -1" range="-0.1 1.3"/>
                                <inertial pos="-0.0048064 0.0009382 -0.00757" mass="0.0018869" fullinertia="5.816E-08 7.9161E-08 6.7433E-08 1.4539E-08 4.491E-09 -1.8727E-09"/>
                                <geom class="visual" mesh="Link11_R"/>
                                <geom class="collision" mesh="Link11_R"/>
                              <body name="R_thumb_proximal" pos="-0.0088099 0.010892 -0.00925" quat="0.099684297 0.099684663 0.70004629 0.70004372">
                                <joint class="inspire" name="R_thumb_proximal_pitch_joint" axis="0 0 1" range="-0.1 0.6"/>
                                  <inertial pos="0.021932 0.012785 -0.0080386" mass="0.0066075" fullinertia="1.5686E-06 1.7353E-06 2.786E-06 -7.8296E-07 8.9143E-10 -1.0191E-09"/>
                                  <geom class="visual" mesh="Link12_R"/>
                                  <geom class="collision" mesh="Link12_R"/>
                                <body name="R_thumb_intermediate" pos="0.04407 0.034553 -0.0008" quat="1 0 0 0">
                                  <joint class="inspire" name="R_thumb_intermediate_joint" axis="0 0 1" range="0 0.8"/>
                                    <inertial pos="0.0095544 -0.0016282 -0.0071997" mass="0.0037847" fullinertia="3.6981E-07 3.2394E-07 4.6531E-07 -9.8581E-08 -4.7469E-12 1.0939E-12"/>
                                    <geom class="visual" mesh="Link13_R"/>
                                    <geom class="collision" mesh="Link13_R"/>
                                  <body name="R_thumb_distal" pos="0.020248 0.010156 -0.0012" quat="1 0 0 0">
                                    <joint class="inspire" name="R_thumb_distal_joint" axis="0 0 1" range="0 1.2"/>
                                      <inertial pos="0.0092888 0.0049529 -0.0060033" mass="0.0033441" fullinertia="1.3632E-07 1.4052E-07 2.0026E-07 -5.6788E-08 -9.2764E-11 -1.2283E-10"/>
                                      <geom class="visual" mesh="Link14_R"/>
                                      <geom class="collision" mesh="Link14_R"/>
                                  </body>
                                </body>
                              </body>
                            </body>
                            <body name="R_index_proximal" pos="0.00028533 -0.13653 -0.032268" quat="0.017445442 -0.99984782 0 0">
                              <joint class="inspire" name="R_index_proximal_joint" axis="0 0 1" range="0 1.7"/>
                                <inertial pos="0.0012259 0.011942 -0.0060001" mass="0.0042403" fullinertia="6.6232E-07 2.1146E-07 6.9398E-07 -1.5775E-08 1.8515E-12 -5.0828E-12"/>
                                <geom class="visual" mesh="Link15_R"/>
                                <geom class="collision" mesh="Link15_R"/>
                              <body name="R_index_intermediate" pos="-0.0026138 0.032026 -0.001" quat="1 0 0 0">
                                <joint class="inspire" name="R_index_intermediate_joint" axis="0 0 1" range="0 1.7"/>
                                  <inertial pos="0.0019697 0.019589 -0.005" mass="0.0045683" fullinertia="7.6111E-07 9.6076E-08 7.8179E-07 8.7637E-08 -3.7751E-13 9.9444E-13"/>
                                  <geom class="visual" mesh="Link16_R"/>
                                  <geom class="collision" mesh="Link16_R"/>
                              </body>
                            </body>
                            <body name="R_middle_proximal" pos="0.00028533 -0.1371 -0.01295" quat="-3.6732051e-06 -1 0 0">
                              <joint class="inspire" name="R_middle_proximal_joint" axis="0 0 1" range="0 1.7"/>
                                <inertial pos="0.001297 0.011934 -0.0060001" mass="0.0042403" fullinertia="6.6211E-07 2.1167E-07 6.9397E-07 -1.8461E-08 1.8002E-12 -6.6808E-12"/>
                                <geom class="visual" mesh="Link17_R"/>
                                <geom class="collision" mesh="Link17_R"/>
                              <body name="R_middle_intermediate" pos="-0.0024229 0.032041 -0.001" quat="1 0 0 0">
                                <joint class="inspire" name="R_middle_intermediate_joint" axis="0 0 1" range="0 1.7"/>
                                  <inertial pos="0.001921 0.020796 -0.005" mass="0.0050396" fullinertia="9.5822E-07 1.0646E-07 9.8384E-07 1.1425E-07 -2.4791E-12 5.9173E-12"/>
                                  <geom class="visual" mesh="Link18_R"/>
                                  <geom class="collision" mesh="Link18_R"/>
                              </body>
                            </body>
                            <body name="R_ring_proximal" pos="0.00028533 -0.13691 0.0062872" quat="0.026193331 0.9996569 0 0">
                              <joint class="inspire" name="R_ring_proximal_joint" axis="0 0 1" range="0 1.7"/>
                                <inertial pos="0.001297 0.011934 -0.0060002" mass="0.0042403" fullinertia="6.6211E-07 2.1167E-07 6.9397E-07 -1.8461E-08 1.5793E-12 -6.6868E-12"/>
                                <geom class="visual" mesh="Link19_R"/>
                                <geom class="collision" mesh="Link19_R"/>
                              <body name="R_ring_intermediate" pos="-0.0024229 0.032041 -0.001" quat="1 0 0 0">
                                <joint class="inspire" name="R_ring_intermediate_joint" axis="0 0 1" range="0 1.7"/>
                                  <inertial pos="0.0021753 0.019567 -0.005" mass="0.0045683" fullinertia="7.6286E-07 9.431E-08 7.8177E-07 8.0635E-08 -6.1562E-13 5.8619E-13"/>
                                  <geom class="visual" mesh="Link20_R"/>
                                  <geom class="collision" mesh="Link20_R"/>
                              </body>
                            </body>
                            <body name="R_pinky_proximal" pos="0.00028533 -0.13571 0.025488" quat="0.052322424 0.99863024 0 0">
                              <joint class="inspire" name="R_pinky_proximal_joint" axis="0 0 1" range="0 1.7"/>
                                <inertial pos="0.001297 0.011934 -0.0060001" mass="0.0042403" fullinertia="6.6211E-07 2.1167E-07 6.9397E-07 -1.8461E-08 1.6907E-12 -6.9334E-12"/>
                                <geom class="visual" mesh="Link21_R"/>
                                <geom class="collision" mesh="Link21_R"/>
                              <body name="R_pinky_intermediate" pos="-0.0024229 0.032041 -0.001" quat="1 0 0 0">
                                <joint class="inspire" name="R_pinky_intermediate_joint" axis="0 0 1" range="0 1.7"/>
                                  <inertial pos="0.0024748 0.016203 -0.0050031" mass="0.0035996" fullinertia="4.3913E-07 7.0247E-08 4.4867E-07 4.1418E-08 3.7168E-11 5.8613E-11"/>
                                  <geom class="visual" mesh="Link22_R"/>
                                  <geom class="collision" mesh="Link22_R"/>
                              </body>
                            </body>
                          </body>
                        </body>
                      </body>
                    </body>
                  </body>
                </body>
              </body>
            </body>
          </body>
        </body>
      </body>
    </body>
  </worldbody>

  <actuator>
    <position class="g1" name="left_hip_pitch_joint" joint="left_hip_pitch_joint"/>
    <position class="g1" name="left_hip_roll_joint" joint="left_hip_roll_joint"/>
    <position class="g1" name="left_hip_yaw_joint" joint="left_hip_yaw_joint"/>
    <position class="g1" name="left_knee_joint" joint="left_knee_joint"/>
    <position class="g1" name="left_ankle_pitch_joint" joint="left_ankle_pitch_joint"/>
    <position class="g1" name="left_ankle_roll_joint" joint="left_ankle_roll_joint"/>

    <position class="g1" name="right_hip_pitch_joint" joint="right_hip_pitch_joint"/>
    <position class="g1" name="right_hip_roll_joint" joint="right_hip_roll_joint"/>
    <position class="g1" name="right_hip_yaw_joint" joint="right_hip_yaw_joint"/>
    <position class="g1" name="right_knee_joint" joint="right_knee_joint"/>
    <position class="g1" name="right_ankle_pitch_joint" joint="right_ankle_pitch_joint"/>
    <position class="g1" name="right_ankle_roll_joint" joint="right_ankle_roll_joint"/>

    <position class="g1" name="waist_yaw_joint" joint="waist_yaw_joint"/>
    <position class="g1" name="waist_roll_joint" joint="waist_roll_joint"/>
    <position class="g1" name="waist_pitch_joint" joint="waist_pitch_joint"/>

    <position class="g1" name="left_shoulder_pitch_joint" joint="left_shoulder_pitch_joint"/>
    <position class="g1" name="left_shoulder_roll_joint" joint="left_shoulder_roll_joint"/>
    <position class="g1" name="left_shoulder_yaw_joint" joint="left_shoulder_yaw_joint"/>
    <position class="g1" name="left_elbow_joint" joint="left_elbow_joint"/>
    <position class="g1" name="left_wrist_roll_joint" joint="left_wrist_roll_joint"/>
    <position class="g1" name="left_wrist_pitch_joint" joint="left_wrist_pitch_joint"/>
    <position class="g1" name="left_wrist_yaw_joint" joint="left_wrist_yaw_joint"/>

    <position class="g1" name="right_shoulder_pitch_joint" joint="right_shoulder_pitch_joint"/>
    <position class="g1" name="right_shoulder_roll_joint" joint="right_shoulder_roll_joint"/>
    <position class="g1" name="right_shoulder_yaw_joint" joint="right_shoulder_yaw_joint"/>
    <position class="g1" name="right_elbow_joint" joint="right_elbow_joint"/>
    <position class="g1" name="right_wrist_roll_joint" joint="right_wrist_roll_joint"/>
    <position class="g1" name="right_wrist_pitch_joint" joint="right_wrist_pitch_joint"/>
    <position class="g1" name="right_wrist_yaw_joint" joint="right_wrist_yaw_joint"/>
    <!-- Inspire finger actuators: 1 position/joint, independent (no 6->12 coupling) -->
    <position class="inspire" name="L_thumb_proximal_yaw_joint" joint="L_thumb_proximal_yaw_joint" ctrlrange="-0.1 1.3"/>
    <position class="inspire" name="L_thumb_proximal_pitch_joint" joint="L_thumb_proximal_pitch_joint" ctrlrange="-0.1 0.6"/>
    <position class="inspire" name="L_thumb_intermediate_joint" joint="L_thumb_intermediate_joint" ctrlrange="0 0.8"/>
    <position class="inspire" name="L_thumb_distal_joint" joint="L_thumb_distal_joint" ctrlrange="0 1.2"/>
    <position class="inspire" name="L_index_proximal_joint" joint="L_index_proximal_joint" ctrlrange="0 1.7"/>
    <position class="inspire" name="L_index_intermediate_joint" joint="L_index_intermediate_joint" ctrlrange="0 1.7"/>
    <position class="inspire" name="L_middle_proximal_joint" joint="L_middle_proximal_joint" ctrlrange="0 1.7"/>
    <position class="inspire" name="L_middle_intermediate_joint" joint="L_middle_intermediate_joint" ctrlrange="0 1.7"/>
    <position class="inspire" name="L_ring_proximal_joint" joint="L_ring_proximal_joint" ctrlrange="0 1.7"/>
    <position class="inspire" name="L_ring_intermediate_joint" joint="L_ring_intermediate_joint" ctrlrange="0 1.7"/>
    <position class="inspire" name="L_pinky_proximal_joint" joint="L_pinky_proximal_joint" ctrlrange="0 1.7"/>
    <position class="inspire" name="L_pinky_intermediate_joint" joint="L_pinky_intermediate_joint" ctrlrange="0 1.7"/>
    <position class="inspire" name="R_thumb_proximal_yaw_joint" joint="R_thumb_proximal_yaw_joint" ctrlrange="-0.1 1.3"/>
    <position class="inspire" name="R_thumb_proximal_pitch_joint" joint="R_thumb_proximal_pitch_joint" ctrlrange="-0.1 0.6"/>
    <position class="inspire" name="R_thumb_intermediate_joint" joint="R_thumb_intermediate_joint" ctrlrange="0 0.8"/>
    <position class="inspire" name="R_thumb_distal_joint" joint="R_thumb_distal_joint" ctrlrange="0 1.2"/>
    <position class="inspire" name="R_index_proximal_joint" joint="R_index_proximal_joint" ctrlrange="0 1.7"/>
    <position class="inspire" name="R_index_intermediate_joint" joint="R_index_intermediate_joint" ctrlrange="0 1.7"/>
    <position class="inspire" name="R_middle_proximal_joint" joint="R_middle_proximal_joint" ctrlrange="0 1.7"/>
    <position class="inspire" name="R_middle_intermediate_joint" joint="R_middle_intermediate_joint" ctrlrange="0 1.7"/>
    <position class="inspire" name="R_ring_proximal_joint" joint="R_ring_proximal_joint" ctrlrange="0 1.7"/>
    <position class="inspire" name="R_ring_intermediate_joint" joint="R_ring_intermediate_joint" ctrlrange="0 1.7"/>
    <position class="inspire" name="R_pinky_proximal_joint" joint="R_pinky_proximal_joint" ctrlrange="0 1.7"/>
    <position class="inspire" name="R_pinky_intermediate_joint" joint="R_pinky_intermediate_joint" ctrlrange="0 1.7"/>
  </actuator>

  <sensor>
    <gyro site="imu_in_torso" name="imu-torso-angular-velocity" cutoff="34.9" noise="0.0005"/>
    <accelerometer site="imu_in_torso" name="imu-torso-linear-acceleration" cutoff="157" noise="0.01"/>
    <gyro site="imu_in_pelvis" name="imu-pelvis-angular-velocity" cutoff="34.9" noise="0.0005"/>
    <accelerometer site="imu_in_pelvis" name="imu-pelvis-linear-acceleration" cutoff="157" noise="0.01"/>
  </sensor>

  <keyframe>
    <key name="stand" qpos="0 0 0.79 1 0 0 0 0 0 0 0 0 0 0 0 0 0 0 0 0 0 0 0.2 0.2 0 1.28 0 0 0 0.2 -0.2 0 1.28 0 0 0"
      ctrl="0 0 0 0 0 0 0 0 0 0 0 0 0 0 0 0.2 0.2 0 1.28 0 0 0 0.2 -0.2 0 1.28 0 0 0"/>
  </keyframe>
</mujoco>
